Workbook

Sheet Bluefin
A1: Reference | B1: Qty | C1: Value | D1: DNP | E1: Exclude from BOM | F1: Exclude from Board | G1: Footprint | H1: Datasheet | I1: LCSC | J1: JLCPCB_CORRECTION | M1: New
A2: C1101,C1102,C1103,C1112 | B2: 4 | C2: 3.3nF | G2: Capacitor_SMD:C_0402_1005Metric | H2: ~ | I2: C26404 | M2: =_xlfn.LET(_xlpm.key,A2,_xlpm.newHash,G2,_xlpm.oldHash,_xlfn.XLOOKUP(_xlpm.key,Halmet!A:A,Halmet!G:G,""),OR(_xlpm.oldHash="",_xlpm.oldHash<>_xlpm.newHash)) -> FALSE
A3: C1104,C1105,C1106,C1107 | B3: 4 | C3: 220pF | G3: Resistor_SMD:R_0402_1005Metric | H3: ~ | I3: C1530 | M3: =_xlfn.LET(_xlpm.key,A3,_xlpm.newHash,G3,_xlpm.oldHash,_xlfn.XLOOKUP(_xlpm.key,Halmet!A:A,Halmet!G:G,""),OR(_xlpm.oldHash="",_xlpm.oldHash<>_xlpm.newHash)) -> FALSE
A4: C1201,C1202,C1208,C1210 | B4: 4 | C4: 4.7uF | G4: Capacitor_SMD:C_0402_1005Metric | H4: ~ | I4: C23733 | M4: =_xlfn.LET(_xlpm.key,A4,_xlpm.newHash,G4,_xlpm.oldHash,_xlfn.XLOOKUP(_xlpm.key,Halmet!A:A,Halmet!G:G,""),OR(_xlpm.oldHash="",_xlpm.oldHash<>_xlpm.newHash)) -> FALSE
A5: C1203 | B5: 1 | C5: 10uF/10V | G5: Capacitor_SMD:C_0603_1608Metric | H5: ~ | I5: C19702 | M5: =_xlfn.LET(_xlpm.key,A5,_xlpm.newHash,G5,_xlpm.oldHash,_xlfn.XLOOKUP(_xlpm.key,Halmet!A:A,Halmet!G:G,""),OR(_xlpm.oldHash="",_xlpm.oldHash<>_xlpm.newHash)) -> FALSE
A6: C1209 | B6: 1 | C6: 220pF/2kV | G6: HALMET:C_1808_4520Metric | H6: ~ | I6: C2940747 | M6: =_xlfn.LET(_xlpm.key,A6,_xlpm.newHash,G6,_xlpm.oldHash,_xlfn.XLOOKUP(_xlpm.key,Halmet!A:A,Halmet!G:G,""),OR(_xlpm.oldHash="",_xlpm.oldHash<>_xlpm.newHash)) -> FALSE
A7: C202 | B7: 1 | C7: 22uF | G7: Capacitor_SMD:C_0603_1608Metric | H7: ~ | I7: C59461 | M7: =_xlfn.LET(_xlpm.key,A7,_xlpm.newHash,G7,_xlpm.oldHash,_xlfn.XLOOKUP(_xlpm.key,Halmet!A:A,Halmet!G:G,""),OR(_xlpm.oldHash="",_xlpm.oldHash<>_xlpm.newHash)) -> FALSE
A8: C203 | B8: 1 | C8: 1uF | G8: Capacitor_SMD:C_0402_1005Metric | H8: ~ | I8: C52923 | M8: =_xlfn.LET(_xlpm.key,A8,_xlpm.newHash,G8,_xlpm.oldHash,_xlfn.XLOOKUP(_xlpm.key,Halmet!A:A,Halmet!G:G,""),OR(_xlpm.oldHash="",_xlpm.oldHash<>_xlpm.newHash)) -> FALSE
A9: C304 | B9: 1 | C9: 47uF/6.3V | G9: Capacitor_SMD:C_1206_3216Metric | H9: ~ | I9: C96123 | M9: =_xlfn.LET(_xlpm.key,A9,_xlpm.newHash,G9,_xlpm.oldHash,_xlfn.XLOOKUP(_xlpm.key,Halmet!A:A,Halmet!G:G,""),OR(_xlpm.oldHash="",_xlpm.oldHash<>_xlpm.newHash)) -> FALSE
A10: C402 | B10: 1 | C10: 4.7uF/16V | G10: Capacitor_SMD:C_0603_1608Metric | H10: ~ | I10: C19666 | M10: =_xlfn.LET(_xlpm.key,A10,_xlpm.newHash,G10,_xlpm.oldHash,_xlfn.XLOOKUP(_xlpm.key,Halmet!A:A,Halmet!G:G,""),OR(_xlpm.oldHash="",_xlpm.oldHash<>_xlpm.newHash)) -> FALSE
A11: C403,C404 | B11: 2 | C11: 10pF/50V | E11: Excluded from BOM | G11: Capacitor_SMD:C_0402_1005Metric | H11: ~ | I11: C32949 | M11: =_xlfn.LET(_xlpm.key,A11,_xlpm.newHash,G11,_xlpm.oldHash,_xlfn.XLOOKUP(_xlpm.key,Halmet!A:A,Halmet!G:G,""),OR(_xlpm.oldHash="",_xlpm.oldHash<>_xlpm.newHash)) -> FALSE
A12: C501,C502 | B12: 2 | C12: 100nF/50V | G12: Capacitor_SMD:C_0603_1608Metric | H12: ~ | I12: C14663 | M12: =_xlfn.LET(_xlpm.key,A12,_xlpm.newHash,G12,_xlpm.oldHash,_xlfn.XLOOKUP(_xlpm.key,Halmet!A:A,Halmet!G:G,""),OR(_xlpm.oldHash="",_xlpm.oldHash<>_xlpm.newHash)) -> FALSE
A13: C503,C715 | B13: 2 | C13: 1uF/50V | G13: Capacitor_SMD:C_0805_2012Metric | H13: ~ | I13: C28323 | M13: =_xlfn.LET(_xlpm.key,A13,_xlpm.newHash,G13,_xlpm.oldHash,_xlfn.XLOOKUP(_xlpm.key,Halmet!A:A,Halmet!G:G,""),OR(_xlpm.oldHash="",_xlpm.oldHash<>_xlpm.newHash)) -> FALSE
A14: C601,C604,C612,C614,C705,C706 | B14: 6 | C14: 33pF/50V | G14: Capacitor_SMD:C_0603_1608Metric | H14: ~ | I14: C1663 | M14: =_xlfn.LET(_xlpm.key,A14,_xlpm.newHash,G14,_xlpm.oldHash,_xlfn.XLOOKUP(_xlpm.key,Halmet!A:A,Halmet!G:G,""),OR(_xlpm.oldHash="",_xlpm.oldHash<>_xlpm.newHash)) -> FALSE
A15: C602,C606,C607,C608,C609,C610,C616,C624,C901,C1113,C1114,C1115,C1116,C1204,C1205,C1206,C1207 | B15: 17 | C15: 100nF | G15: Capacitor_SMD:C_0402_1005Metric | H15: ~ | I15: C1525 | M15: =_xlfn.LET(_xlpm.key,A15,_xlpm.newHash,G15,_xlpm.oldHash,_xlfn.XLOOKUP(_xlpm.key,Halmet!A:A,Halmet!G:G,""),OR(_xlpm.oldHash="",_xlpm.oldHash<>_xlpm.newHash)) -> TRUE
A16: C603,C605,C613,C615,C702,C703 | B16: 6 | C16: 33pF | G16: Capacitor_SMD:C_0402_1005Metric | H16: ~ | I16: C1562 | M16: =_xlfn.LET(_xlpm.key,A16,_xlpm.newHash,G16,_xlpm.oldHash,_xlfn.XLOOKUP(_xlpm.key,Halmet!A:A,Halmet!G:G,""),OR(_xlpm.oldHash="",_xlpm.oldHash<>_xlpm.newHash)) -> FALSE
A17: C611 | B17: 1 | C17: 68nF | G17: Capacitor_SMD:C_0603_1608Metric | H17: ~ | I17: C31658 | M17: =_xlfn.LET(_xlpm.key,A17,_xlpm.newHash,G17,_xlpm.oldHash,_xlfn.XLOOKUP(_xlpm.key,Halmet!A:A,Halmet!G:G,""),OR(_xlpm.oldHash="",_xlpm.oldHash<>_xlpm.newHash)) -> FALSE
A18: C620,C621,C622,C623 | B18: 4 | C18: 10nF | G18: Capacitor_SMD:C_0402_1005Metric | H18: ~ | I18: C15195 | M18: =_xlfn.LET(_xlpm.key,A18,_xlpm.newHash,G18,_xlpm.oldHash,_xlfn.XLOOKUP(_xlpm.key,Halmet!A:A,Halmet!G:G,""),OR(_xlpm.oldHash="",_xlpm.oldHash<>_xlpm.newHash)) -> FALSE
A19: C701,C801 | B19: 2 | C19: 10uF | G19: Capacitor_SMD:C_0402_1005Metric | H19: ~ | I19: C15525 | M19: =_xlfn.LET(_xlpm.key,A19,_xlpm.newHash,G19,_xlpm.oldHash,_xlfn.XLOOKUP(_xlpm.key,Halmet!A:A,Halmet!G:G,""),OR(_xlpm.oldHash="",_xlpm.oldHash<>_xlpm.newHash)) -> FALSE
A20: C704,C707,C708,C709,C710,C711,C712,C714,C721,C803 | B20: 10 | C20: 10uF/50V | G20: Capacitor_SMD:C_1206_3216Metric | H20: ~ | I20: C13585 | M20: =_xlfn.LET(_xlpm.key,A20,_xlpm.newHash,G20,_xlpm.oldHash,_xlfn.XLOOKUP(_xlpm.key,Halmet!A:A,Halmet!G:G,""),OR(_xlpm.oldHash="",_xlpm.oldHash<>_xlpm.newHash)) -> TRUE
A21: C713 | B21: 1 | C21: 4.7nF/50V | G21: Capacitor_SMD:C_0402_1005Metric | H21: ~ | I21: C1538 | M21: =_xlfn.LET(_xlpm.key,A21,_xlpm.newHash,G21,_xlpm.oldHash,_xlfn.XLOOKUP(_xlpm.key,Halmet!A:A,Halmet!G:G,""),OR(_xlpm.oldHash="",_xlpm.oldHash<>_xlpm.newHash)) -> FALSE
A22: C716 | B22: 1 | C22: 4.7uF/50V | G22: Capacitor_SMD:C_1206_3216Metric | H22: ~ | I22: C29823 | M22: =_xlfn.LET(_xlpm.key,A22,_xlpm.newHash,G22,_xlpm.oldHash,_xlfn.XLOOKUP(_xlpm.key,Halmet!A:A,Halmet!G:G,""),OR(_xlpm.oldHash="",_xlpm.oldHash<>_xlpm.newHash)) -> FALSE
A23: C717,C720 | B23: 2 | C23: 0.1uF/50V | G23: Capacitor_SMD:C_1206_3216Metric | H23: ~ | I23: C24497 | M23: =_xlfn.LET(_xlpm.key,A23,_xlpm.newHash,G23,_xlpm.oldHash,_xlfn.XLOOKUP(_xlpm.key,Halmet!A:A,Halmet!G:G,""),OR(_xlpm.oldHash="",_xlpm.oldHash<>_xlpm.newHash)) -> TRUE
... A28: D1001,D1002 | B28: 2 | C28: GREEN LED | G28: LED_SMD:LED_0603_1608Metric | H28: ~ | I28: C965804 | M28: =_xlfn.LET(_xlpm.key,A28,_xlpm.newHash,G28,_xlpm.oldHash,_xlfn.XLOOKUP(_xlpm.key,Halmet!A:A,Halmet!G:G,""),OR(_xlpm.oldHash="",_xlpm.oldHash<>_xlpm.newHash)) -> FALSE
A29: D1101,D1102 | B29: 2 | C29: BAT54A | G29: Package_TO_SOT_SMD:SOT-323_SC-70 | I29: C78261 | J29: 0;0;180 | M29: =_xlfn.LET(_xlpm.key,A29,_xlpm.newHash,G29,_xlpm.oldHash,_xlfn.XLOOKUP(_xlpm.key,Halmet!A:A,Halmet!G:G,""),OR(_xlpm.oldHash="",_xlpm.oldHash<>_xlpm.newHash)) -> FALSE
A30: D201,D303,D701 | B30: 3 | C30: B5819W | G30: Diode_SMD:D_SOD-123 | H30: ~ | I30: C8598 | M30: =_xlfn.LET(_xlpm.key,A30,_xlpm.newHash,G30,_xlpm.oldHash,_xlfn.XLOOKUP(_xlpm.key,Halmet!A:A,Halmet!G:G,""),OR(_xlpm.oldHash="",_xlpm.oldHash<>_xlpm.newHash)) -> FALSE
A31: D301 | B31: 1 | C31: SMBJ33CA | G31: Diode_SMD:D_SMB | H31: ~ | I31: C114000 | M31: =_xlfn.LET(_xlpm.key,A31,_xlpm.newHash,G31,_xlpm.oldHash,_xlfn.XLOOKUP(_xlpm.key,Halmet!A:A,Halmet!G:G,""),OR(_xlpm.oldHash="",_xlpm.oldHash<>_xlpm.newHash)) -> FALSE
A32: D401,D402,D403,D503,D504,D903,D904,D905 | B32: 8 | C32: ESD5451N | G32: Diode_SMD:D_0402_1005Metric | H32: ~ | I32: C2936977 | M32: =_xlfn.LET(_xlpm.key,A32,_xlpm.newHash,G32,_xlpm.oldHash,_xlfn.XLOOKUP(_xlpm.key,Halmet!A:A,Halmet!G:G,""),OR(_xlpm.oldHash="",_xlpm.oldHash<>_xlpm.newHash)) -> FALSE
A33: D501 | B33: 1 | C33: BLUE LED | G33: LED_SMD:LED_0603_1608Metric | H33: ~ | I33: C84266 | M33: =_xlfn.LET(_xlpm.key,A33,_xlpm.newHash,G33,_xlpm.oldHash,_xlfn.XLOOKUP(_xlpm.key,Halmet!A:A,Halmet!G:G,""),OR(_xlpm.oldHash="",_xlpm.oldHash<>_xlpm.newHash)) -> FALSE
A34: D502 | B34: 1 | C34: RED LED | G34: LED_SMD:LED_0603_1608Metric | H34: ~ | I34: C2286 | M34: =_xlfn.LET(_xlpm.key,A34,_xlpm.newHash,G34,_xlpm.oldHash,_xlfn.XLOOKUP(_xlpm.key,Halmet!A:A,Halmet!G:G,""),OR(_xlpm.oldHash="",_xlpm.oldHash<>_xlpm.newHash)) -> FALSE
A35: D603,D604,D605,D611,D1103,D1104,D1105,D1113 | B35: 8 | C35: BAT54S | G35: Package_TO_SOT_SMD:SOT-323_SC-70 | H35: https://www.diodes.com/assets/Datasheets/ds11005.pdf | I35: C12741 | J35: 0;0;180 | M35: =_xlfn.LET(_xlpm.key,A35,_xlpm.newHash,G35,_xlpm.oldHash,_xlfn.XLOOKUP(_xlpm.key,Halmet!A:A,Halmet!G:G,""),OR(_xlpm.oldHash="",_xlpm.oldHash<>_xlpm.newHash)) -> FALSE
A36: D801 | B36: 1 | C36: SM24CANB | G36: Package_TO_SOT_SMD:SOT-23 | H36: ~ | I36: C41376477 | J36: 0;0;180 | M36: =_xlfn.LET(_xlpm.key,A36,_xlpm.newHash,G36,_xlpm.oldHash,_xlfn.XLOOKUP(_xlpm.key,Halmet!A:A,Halmet!G:G,""),OR(_xlpm.oldHash="",_xlpm.oldHash<>_xlpm.newHash)) -> FALSE
A37: F301 | B37: 1 | C37: mSMD050-60V | G37: Fuse:Fuse_1812_4532Metric | H37: ~ | I37: C70113 | M37: =_xlfn.LET(_xlpm.key,A37,_xlpm.newHash,G37,_xlpm.oldHash,_xlfn.XLOOKUP(_xlpm.key,Halmet!A:A,Halmet!G:G,""),OR(_xlpm.oldHash="",_xlpm.oldHash<>_xlpm.newHash)) -> FALSE
A38: F401 | B38: 1 | C38: BSMD1206-100-6V | G38: Fuse:Fuse_1206_3216Metric | H38: https://datasheet.lcsc.com/lcsc/2305121423_BHFUSE-BSMD1206-100-6V_C883129.pdf | I38: C883129 | M38: =_xlfn.LET(_xlpm.key,A38,_xlpm.newHash,G38,_xlpm.oldHash,_xlfn.XLOOKUP(_xlpm.key,Halmet!A:A,Halmet!G:G,""),OR(_xlpm.oldHash="",_xlpm.oldHash<>_xlpm.newHash)) -> FALSE
A39: F501,F502 | B39: 2 | C39: 1206L010/60WR | G39: 1206L010_60WR:1206L075132WR | H39: ~ | I39: C2153714 | M39: =_xlfn.LET(_xlpm.key,A39,_xlpm.newHash,G39,_xlpm.oldHash,_xlfn.XLOOKUP(_xlpm.key,Halmet!A:A,Halmet!G:G,""),OR(_xlpm.oldHash="",_xlpm.oldHash<>_xlpm.newHash)) -> TRUE
A40: FB401,FB701,FB704,FB801 | B40: 4 | C40: GZ2012D601TF | G40: Inductor_SMD:L_0805_2012Metric | H40: ~ | I40: C1017 | M40: =_xlfn.LET(_xlpm.key,A40,_xlpm.newHash,G40,_xlpm.oldHash,_xlfn.XLOOKUP(_xlpm.key,Halmet!A:A,Halmet!G:G,""),OR(_xlpm.oldHash="",_xlpm.oldHash<>_xlpm.newHash)) -> FALSE
A41: FB601,FB602,FB603,FB604,FB702,FB703 | B41: 6 | C41: GZ2012D101TF | G41: Inductor_SMD:L_0805_2012Metric | H41: ~ | I41: C1015 | M41: =_xlfn.LET(_xlpm.key,A41,_xlpm.newHash,G41,_xlpm.oldHash,_xlfn.XLOOKUP(_xlpm.key,Halmet!A:A,Halmet!G:G,""),OR(_xlpm.oldHash="",_xlpm.oldHash<>_xlpm.newHash)) -> FALSE
A42: G601 | B42: 1 | C42: CC-BY | E42: Excluded from BOM | G42: HALMET:cc-by_5mm | H42: ~ | M42: =_xlfn.LET(_xlpm.key,A42,_xlpm.newHash,G42,_xlpm.oldHash,_xlfn.XLOOKUP(_xlpm.key,Halmet!A:A,Halmet!G:G,""),OR(_xlpm.oldHash="",_xlpm.oldHash<>_xlpm.newHash)) -> FALSE
A43: G602 | B43: 1 | C43: CE-logo | E43: Excluded from BOM | G43: Symbol:CE-Logo_11.2x8mm_SilkScreen | H43: ~ | M43: =_xlfn.LET(_xlpm.key,A43,_xlpm.newHash,G43,_xlpm.oldHash,_xlfn.XLOOKUP(_xlpm.key,Halmet!A:A,Halmet!G:G,""),OR(_xlpm.oldHash="",_xlpm.oldHash<>_xlpm.newHash)) -> FALSE
A44: G603 | B44: 1 | C44: WEEE-logo | E44: Excluded from BOM | F44: Excluded from board | G44: Symbol:WEEE-Logo_5.6x8mm_SilkScreen | H44: ~ | M44: =_xlfn.LET(_xlpm.key,A44,_xlpm.newHash,G44,_xlpm.oldHash,_xlfn.XLOOKUP(_xlpm.key,Halmet!A:A,Halmet!G:G,""),OR(_xlpm.oldHash="",_xlpm.oldHash<>_xlpm.newHash)) -> FALSE
...

Sheet Halmet
A1: Reference | B1: Qty | C1: Value | D1: DNP | E1: Exclude from BOM | F1: Exclude from Board | G1: Footprint | H1: Datasheet | I1: LCSC | J1: JLCPCB_CORRECTION
A2: C1101,C1102,C1103,C1112 | B2: 4 | C2: 3.3nF | G2: Capacitor_SMD:C_0402_1005Metric | H2: ~ | I2: C26404
A3: C1104,C1105,C1106,C1107 | B3: 4 | C3: 220pF | G3: Resistor_SMD:R_0402_1005Metric | H3: ~ | I3: C1530
A4: C1201,C1202,C1208,C1210 | B4: 4 | C4: 4.7uF | G4: Capacitor_SMD:C_0402_1005Metric | H4: ~ | I4: C23733
A5: C1203 | B5: 1 | C5: 10uF/10V | G5: Capacitor_SMD:C_0603_1608Metric | H5: ~ | I5: C19702
A6: C1209 | B6: 1 | C6: 220pF/2kV | G6: HALMET:C_1808_4520Metric | H6: ~ | I6: C2940747
A7: C202 | B7: 1 | C7: 22uF | G7: Capacitor_SMD:C_0603_1608Metric | H7: ~ | I7: C59461
A8: C203 | B8: 1 | C8: 1uF | G8: Capacitor_SMD:C_0402_1005Metric | H8: ~ | I8: C52923
A9: C304 | B9: 1 | C9: 47uF/6.3V | G9: Capacitor_SMD:C_1206_3216Metric | H9: ~ | I9: C96123
A10: C402 | B10: 1 | C10: 4.7uF/16V | G10: Capacitor_SMD:C_0603_1608Metric | H10: ~ | I10: C19666
A11: C403,C404 | B11: 2 | C11: 10pF/50V | E11: Excluded from BOM | G11: Capacitor_SMD:C_0402_1005Metric | H11: ~ | I11: C32949
A12: C501,C502 | B12: 2 | C12: 100nF/50V | G12: Capacitor_SMD:C_0603_1608Metric | H12: ~ | I12: C14663
A13: C503,C715 | B13: 2 | C13: 1uF/50V | G13: Capacitor_SMD:C_0805_2012Metric | H13: ~ | I13: C28323
A14: C601,C604,C612,C614,C705,C706 | B14: 6 | C14: 33pF/50V | G14: Capacitor_SMD:C_0603_1608Metric | H14: ~ | I14: C1663
A15: C602,C606,C607,C608,C609,C610,C624,C901,C1113,C1114,C1115,C1116,C1204,C1205,C1206,C1207 | B15: 16 | C15: 100nF | G15: Capacitor_SMD:C_0402_1005Metric | H15: ~ | I15: C1525
A16: C603,C605,C613,C615,C702,C703 | B16: 6 | C16: 33pF | G16: Capacitor_SMD:C_0402_1005Metric | H16: ~ | I16: C1562
A17: C611 | B17: 1 | C17: 68nF | G17: Capacitor_SMD:C_0603_1608Metric | H17: ~ | I17: C31658
A18: C620,C621,C622,C623 | B18: 4 | C18: 10nF | G18: Capacitor_SMD:C_0402_1005Metric | H18: ~ | I18: C15195
A19: C701,C801 | B19: 2 | C19: 10uF | G19: Capacitor_SMD:C_0402_1005Metric | H19: ~ | I19: C15525
A20: C704,C707,C708,C709,C710,C711,C712,C714,C803 | B20: 9 | C20: 10uF/50V | G20: Capacitor_SMD:C_1206_3216Metric | H20: ~ | I20: C13585
A21: C713 | B21: 1 | C21: 4.7nF/50V | G21: Capacitor_SMD:C_0402_1005Metric | H21: ~ | I21: C1538
A22: C716 | B22: 1 | C22: 4.7uF/50V | G22: Capacitor_SMD:C_1206_3216Metric | H22: ~ | I22: C29823
A23: C802 | B23: 1 | C23: 1nF/50V | G23: Capacitor_SMD:C_0603_1608Metric | H23: ~ | I23: C1588
A24: D1001,D1002 | B24: 2 | C24: GREEN LED | G24: LED_SMD:LED_0603_1608Metric | H24: ~ | I24: C965804
A25: D1101,D1102 | B25: 2 | C25: BAT54A | G25: Package_TO_SOT_SMD:SOT-323_SC-70 | I25: C78261 | J25: 0;0;180
A26: D201,D303,D701 | B26: 3 | C26: B5819W | G26: Diode_SMD:D_SOD-123 | H26: ~ | I26: C8598
A27: D301 | B27: 1 | C27: SMBJ33CA | G27: Diode_SMD:D_SMB | H27: ~ | I27: C114000
A28: D401,D402,D403,D503,D504,D903,D904,D905 | B28: 8 | C28: ESD5451N | G28: Diode_SMD:D_0402_1005Metric | H28: ~ | I28: C2936977
A29: D501 | B29: 1 | C29: BLUE LED | G29: LED_SMD:LED_0603_1608Metric | H29: ~ | I29: C84266
A30: D502 | B30: 1 | C30: RED LED | G30: LED_SMD:LED_0603_1608Metric | H30: ~ | I30: C2286
A31: D603,D604,D605,D611,D1103,D1104,D1105,D1113 | B31: 8 | C31: BAT54S | G31: Package_TO_SOT_SMD:SOT-323_SC-70 | H31: https://www.diodes.com/assets/Datasheets/ds11005.pdf | I31: C12741 | J31: 0;0;180
A32: D801 | B32: 1 | C32: SM24CANB | G32: Package_TO_SOT_SMD:SOT-23 | H32: ~ | I32: C41376477 | J32: 0;0;180
A33: F301 | B33: 1 | C33: mSMD050-60V | G33: Fuse:Fuse_1812_4532Metric | H33: ~ | I33: C70113
A34: F401 | B34: 1 | C34: BSMD1206-100-6V | G34: Fuse:Fuse_1206_3216Metric | H34: https://datasheet.lcsc.com/lcsc/2305121423_BHFUSE-BSMD1206-100-6V_C883129.pdf | I34: C883129
A35: FB401,FB701,FB704,FB801 | B35: 4 | C35: GZ2012D601TF | G35: Inductor_SMD:L_0805_2012Metric | H35: ~ | I35: C1017
A36: FB601,FB602,FB603,FB604,FB702,FB703 | B36: 6 | C36: GZ2012D101TF | G36: Inductor_SMD:L_0805_2012Metric | H36: ~ | I36: C1015
A37: G601 | B37: 1 | C37: CC-BY | E37: Excluded from BOM | G37: HALMET:cc-by_5mm | H37: ~
A38: G602 | B38: 1 | C38: CE-logo | E38: Excluded from BOM | G38: Symbol:CE-Logo_11.2x8mm_SilkScreen | H38: ~
A39: G603 | B39: 1 | C39: WEEE-logo | E39: Excluded from BOM | F39: Excluded from board | G39: Symbol:WEEE-Logo_5.6x8mm_SilkScreen | H39: ~
A40: G604 | B40: 1 | C40: OSHW-logo | E40: Excluded from BOM | F40: Excluded from board | G40: Symbol:OSHW-Logo2_9.8x8mm_SilkScreen | H40: ~
...

Sheet Diff
A1: Reference | B1: Qty | C1: Value | D1: DNP | E1: Exclude from BOM | F1: Exclude from Board | G1: Footprint | H1: Datasheet | I1: LCSC | J1: JLCPCB_CORRECTION | M1: Notes
A2: {=_xlfn._xlws.FILTER(Bluefin!A2:J100,Bluefin!M2:M100=TRUE)} -> C602,C606,C607,C608,C609,C610,C616,C624,C901,C1113,C1114,C1115,C1116,C1204,C1205,C1206,C1207 | B2: 17 | C2: 100nF | D2: 0 | E2: 0 | F2: 0 | G2: Capacitor_SMD:C_0402_1005Metric | H2: ~ | I2: C1525 | J2: 0
A3: C704,C707,C708,C709,C710,C711,C712,C714,C721,C803 | B3: 10 | C3: 10uF/50V | D3: 0 | E3: 0 | F3: 0 | G3: Capacitor_SMD:C_1206_3216Metric | H3: ~ | I3: C13585 | J3: 0
A4: C717,C720 | B4: 2 | C4: 0.1uF/50V | D4: 0 | E4: 0 | F4: 0 | G4: Capacitor_SMD:C_1206_3216Metric | H4: ~ | I4: C24497 | J4: 0
A5: C718 | B5: 1 | C5: 2.2uF/50V | D5: 0 | E5: 0 | F5: 0 | G5: Capacitor_SMD:C_1206_3216Metric | H5: ~ | I5: C50254 | J5: 0
A6: C719 | B6: 1 | C6: 10nF/50V | D6: 0 | E6: 0 | F6: 0 | G6: Capacitor_SMD:C_1206_3216Metric | H6: ~ | I6: C153292 | J6: 0
A7: CR501 | B7: 1 | C7: PSM712-LF-T7 | D7: 0 | E7: 0 | F7: 0 | G7: PSM712-LF-T7:CR_SOT-23_PTD | H7: PSM712-LF-T7 | I7: C32677 | J7: 0
A8: F501,F502 | B8: 2 | C8: 1206L010/60WR | D8: 0 | E8: 0 | F8: 0 | G8: 1206L010_60WR:1206L075132WR | H8: ~ | I8: C2153714 | J8: 0
A9: J402 | B9: 1 | C9: Conn_01x04 | D9: 0 | E9: 0 | F9: 0 | G9: Connector_JST:JST_SH_BM04B-SRSS-TB_1x04-1MP_P1.00mm_Vertical | H9: ~ | I9: C160390 | J9: 0
A10: J501 | B10: 1 | C10: EXT LEDS | D10: 0 | E10: 0 | F10: 0 | G10: Connector_PinHeader_2.00mm:PinHeader_1x03_P2.00mm_Vertical | H10: ~ | I10: C541857 | J10: 0
A11: JP1 | B11: 1 | C11: Jumper_2_Small_Open | D11: 0 | E11: 0 | F11: 0 | G11: Connector_PinHeader_2.00mm:PinHeader_1x02_P2.00mm_Vertical | H11: ~ | I11: C541856 | J11: 0
A12: R204,R505 | B12: 2 | C12: 240R | D12: 0 | E12: 0 | F12: 0 | G12: Resistor_SMD:R_0402_1005Metric | H12: ~ | I12: C25094 | J12: 0
A13: R205,R603,R604,R605,R606,R611 | B13: 6 | C13: 1k | D13: 0 | E13: 0 | F13: 0 | G13: Resistor_SMD:R_0402_1005Metric | H13: ~ | I13: C11702 | J13: 0
A14: R206 | B14: 1 | C14: 2.7k | D14: 0 | E14: 0 | F14: 0 | G14: Resistor_SMD:R_0402_1005Metric | H14: ~ | I14: C25885 | J14: 0
A15: R403,R404 | B15: 2 | C15: 27R | D15: 0 | E15: 0 | F15: 0 | G15: Resistor_SMD:R_0201_0603Metric | H15: ~ | I15: C270320 | J15: 0 | M15: Is package too small ?
A16: R504 | B16: 1 | C16: 75R | D16: 0 | E16: 0 | F16: 0 | G16: Resistor_SMD:R_0402_1005Metric | H16: ~ | I16: C25133 | J16: 0
A17: U1200 | B17: 1 | C17: ICM-42688-P | D17: 0 | E17: 0 | F17: 0 | G17: BLUEFIN:PQFN50P300X250X97-14N | H17: https://jlcpcb.com/api/file/downloadByFileSystemAccessId/8588902275431469056 | I17: C1850418 | J17: 0
A18: U201 | B18: 1 | C18: ESP32-S3-WROOM-1U-N16R8 | D18: 0 | E18: 0 | F18: 0 | G18: RF_Module:ESP32-S3-WROOM-1U | H18: https://www.espressif.com/sites/default/files/documentation/esp32-s3-wroom-1_wroom-1u_datasheet_en.pdf | I18: C3013946 | J18: 0;0.75;270 | M18: Is JLCPCB correction relevant ?
A19: U203 | B19: 1 | C19: LM317L_SOT-89 | D19: 0 | E19: 0 | F19: 0 | G19: Package_TO_SOT_SMD:SOT-89-3 | H19: http://www.ti.com/lit/ds/symlink/lm317l.pdf | I19: C5444280 | J19: 0
A20: U402 | B20: 1 | C20: USBLC6-2SC6 | D20: 0 | E20: 0 | F20: 0 | G20: Package_TO_SOT_SMD:SOT-23-6 | H20: https://www.st.com/resource/en/datasheet/usblc6-2.pdf | I20: C7519 | J20: 0
A21: U502 | B21: 1 | C21: SP3485EN | D21: 0 | E21: 0 | F21: 0 | G21: Package_SO:SOIC-8_3.9x4.9mm_P1.27mm | H21: http://www.icbase.com/pdf/SPX/SPX00480106.pdf | I21: C8963 | J21: 0
